<?xml version="1.0" ?>
<!-- =================================================================================== -->
<!-- |    This document was autogenerated by xacro from /home/alex/dev/za_docker/hardware_ws/src/hydra_description/urdf/hydra.xacro | -->
<!-- |    EDITING THIS FILE BY HAND IS NOT RECOMMENDED                                 | -->
<!-- =================================================================================== -->
<robot name="hydra">
    &quot;
    <!-- link list -->
    <link name="rob1_base_link">
        <visual>
            <geometry>
                <mesh filename="package://za_description/meshes/visual/base_link.dae" />
            </geometry>
        </visual>
        <collision>
            <geometry>
                <mesh filename="package://za_description/meshes/collision/base_link_collision.stl" />
            </geometry>
        </collision>
        <inertial>
            <origin xyz="-0.035356 -0.000003 0.142049" rpy="0 0 0" />
            <mass value="18.327" />
            <inertia ixx="0.185203" ixy="0.000006" ixz="0.016506" iyy="0.232301" iyz="0.000014" izz="0.163415" />
        </inertial>
    </link>
    <link name="rob1_link_1">
        <visual>
            <geometry>
                <mesh filename="package://za_description/meshes/visual/link_1.dae" />
            </geometry>
        </visual>
        <collision>
            <geometry>
                <mesh filename="package://za_description/meshes/collision/link_1_collision.stl" />
            </geometry>
        </collision>
        <inertial>
            <origin xyz="0.009612 0.016390 -0.065742" rpy="0 0 0" />
            <mass value="13.44" />
            <inertia ixx="0.178493" ixy="0.002772" ixz="0.010363" iyy="0.126756" iyz="0.016161" izz="0.130031" />
        </inertial>
    </link>
    <link name="rob1_link_2">
        <visual>
            <geometry>
                <mesh filename="package://za_description/meshes/visual/link_2.dae" />
            </geometry>
        </visual>
        <collision>
            <geometry>
                <mesh filename="package://za_description/meshes/collision/link_2_collision.stl" />
            </geometry>
        </collision>
        <inertial>
            <origin xyz="-0.003803 0.001296 0.191397" rpy="0 0 0" />
            <mass value="17.11" />
            <inertia ixx="0.740919" ixy="-0.003160" ixz="-0.003160" iyy="0.699365" iyz="0.039435" izz="0.100361" />
        </inertial>
    </link>
    <link name="rob1_link_3">
        <visual>
            <geometry>
                <mesh filename="package://za_description/meshes/visual/link_3.dae" />
            </geometry>
        </visual>
        <collision>
            <geometry>
                <mesh filename="package://za_description/meshes/collision/link_3_collision.stl" />
            </geometry>
        </collision>
        <inertial>
            <origin xyz="0.019381 -0.007200 -0.002694" rpy="0 0 0" />
            <mass value="7.33" />
            <inertia ixx="0.027465" ixy="0.001126" ixz="0.004749" iyy="0.037555" iyz="-0.000148" izz="0.031377" />
        </inertial>
    </link>
    <link name="rob1_link_4">
        <visual>
            <geometry>
                <mesh filename="package://za_description/meshes/visual/link_4.dae" />
            </geometry>
        </visual>
        <collision>
            <geometry>
                <mesh filename="package://za_description/meshes/collision/link_4_collision.stl" />
            </geometry>
        </collision>
        <inertial>
            <origin xyz="0.290062 0.005593 0.000640" rpy="0 0 0" />
            <mass value="6.11" />
            <inertia ixx="0.019909" ixy="0.003159" ixz="-0.000103" iyy="0.058941" iyz="-0.000022" izz="0.066959" />
        </inertial>
    </link>
    <link name="rob1_link_5">
        <visual>
            <geometry>
                <mesh filename="package://za_description/meshes/visual/link_5.dae" />
            </geometry>
        </visual>
        <collision>
            <geometry>
                <mesh filename="package://za_description/meshes/collision/link_5_collision.stl" />
            </geometry>
        </collision>
        <inertial>
            <origin xyz="0.009621 0.000953 0.000305" rpy="0 0 0" />
            <mass value="2.44" />
            <inertia ixx="0.002635" ixy="-0.000031" ixz="-0.000023" iyy="0.005551" iyz="0.000004" izz="0.005487" />
        </inertial>
    </link>
    <link name="rob1_link_6">
        <visual>
            <geometry>
                <mesh filename="package://za_description/meshes/visual/link_6.dae" />
            </geometry>
        </visual>
        <collision>
            <geometry>
                <mesh filename="package://za_description/meshes/collision/link_6_collision.stl" />
            </geometry>
        </collision>
        <inertial>
            <origin xyz="-0.012049 0.000000 0.000000" rpy="0 0 0" />
            <mass value="0.244" />
            <inertia ixx="0.000106" ixy="0.000000" ixz="0.000000" iyy="0.000064" iyz="0.000000" izz="0.000064" />
        </inertial>
    </link>
    <!-- joint list -->
    <joint name="rob1_joint_1" type="revolute">
        <origin rpy="0.0 0.0 0.0" xyz="0 0 0.45" />
        <axis xyz="0 0 1" />
        <parent link="rob1_base_link" />
        <child link="rob1_link_1" />
        <limit effort="500.0" lower="-2.96" upper="2.96" velocity="2.6" />
        <dynamics damping="0.003" friction="0.0" />
    </joint>
    <joint name="rob1_joint_2" type="revolute">
        <origin rpy="0.0 0.0 0.0" xyz="0.025 0 0.0" />
        <axis xyz="0 1 0" />
        <parent link="rob1_link_1" />
        <child link="rob1_link_2" />
        <limit effort="500.0" lower="-1.74" upper="2.35" velocity="1.9" />
        <dynamics damping="0.003" friction="0.0" />
    </joint>
    <joint name="rob1_joint_3" type="revolute">
        <origin rpy="0.0 0.0 0.0" xyz="0.0 -0.001 0.454" />
        <axis xyz="0 1 0" />
        <parent link="rob1_link_2" />
        <child link="rob1_link_3" />
        <limit effort="200.0" lower="-1.570796" upper="1.15" velocity="2.6" />
        <dynamics damping="0.003" friction="0.0" />
    </joint>
    <joint name="rob1_joint_4" type="revolute">
        <origin rpy="0.0 0.0 0.0" xyz="0.0 0.0 0.035" />
        <axis xyz="1 0 0" />
        <parent link="rob1_link_3" />
        <child link="rob1_link_4" />
        <limit effort="100.0" lower="-2.6" upper="2.6" velocity="3.5" />
        <dynamics damping="0.003" friction="0.0" />
    </joint>
    <joint name="rob1_joint_5" type="revolute">
        <origin rpy="0.0 0.0 0.0" xyz="0.4195 0.001 0.0" />
        <axis xyz="0 1 0" />
        <parent link="rob1_link_4" />
        <child link="rob1_link_5" />
        <limit effort="100.0" lower="-2.49" upper="2.49" velocity="3.9" />
        <dynamics damping="0.003" friction="0.0" />
    </joint>
    <joint name="rob1_joint_6" type="revolute">
        <origin rpy="0.0 0.0 0.0" xyz="0.1175 0.0 0.0" />
        <axis xyz="1 0 0" />
        <parent link="rob1_link_5" />
        <child link="rob1_link_6" />
        <limit effort="10.0" lower="-3.141592653589793" upper="3.141592653589793" velocity="6.283185307179586" />
        <dynamics damping="0.003" friction="0.0" />
    </joint>
    <!-- ROS-Industrial 'base' frame: base_link to Fanuc World Coordinates transform -->
    <link name="rob1_base" />
    <joint name="rob1_base_link-base" type="fixed">
        <origin rpy="0 0 0" xyz="0 0 0" />
        <axis xyz="0 0 1" />
        <parent link="rob1_base_link" />
        <child link="rob1_base" />
    </joint>
    <!-- ROS-Industrial 'flange' frame: attachment point for EEF models -->
    <link name="rob1_flange" />
    <joint name="rob1_joint_6-flange" type="fixed">
        <origin rpy="0 0 0" xyz="0 0 0" />
        <parent link="rob1_link_6" />
        <child link="rob1_flange" />
    </joint>
    <!-- ROS-Industrial 'tool0' frame: all-zeros tool frame -->
    <link name="rob1_tool0" />
    <joint name="rob1_link_6_tool0" type="fixed">
        <origin rpy="0 1.5707963267948966 0" xyz="0 0 0" />
        <parent link="rob1_flange" />
        <child link="rob1_tool0" />
    </joint>
    <transmission name="rob1_joint_1_transmission">
        <type>transmission_interface/SimpleTransmission</type>
        <joint name="rob1_joint_1">
            <hardwareInterface>hardware_interface/EffortJointInterface</hardwareInterface>
        </joint>
        <actuator name="rob1_joint_1_motor">
            <hardwareInterface>hardware_interface/EffortJointInterface</hardwareInterface>
            <mechanicalReduction>1.5</mechanicalReduction>
        </actuator>
    </transmission>
    <transmission name="rob1_joint_2_transmission">
        <type>transmission_interface/SimpleTransmission</type>
        <joint name="rob1_joint_2">
            <hardwareInterface>hardware_interface/EffortJointInterface</hardwareInterface>
        </joint>
        <actuator name="rob1_joint_2_motor">
            <hardwareInterface>hardware_interface/EffortJointInterface</hardwareInterface>
            <mechanicalReduction>100</mechanicalReduction>
        </actuator>
    </transmission>
    <transmission name="rob1_joint_3_transmission">
        <type>transmission_interface/SimpleTransmission</type>
        <joint name="rob1_joint_3">
            <hardwareInterface>hardware_interface/EffortJointInterface</hardwareInterface>
        </joint>
        <actuator name="rob1_joint_3_motor">
            <hardwareInterface>hardware_interface/EffortJointInterface</hardwareInterface>
            <mechanicalReduction>50</mechanicalReduction>
        </actuator>
    </transmission>
    <transmission name="rob1_joint_4_transmission">
        <type>transmission_interface/SimpleTransmission</type>
        <joint name="rob1_joint_4">
            <hardwareInterface>hardware_interface/EffortJointInterface</hardwareInterface>
        </joint>
        <actuator name="rob1_joint_4_motor">
            <hardwareInterface>hardware_interface/EffortJointInterface</hardwareInterface>
            <mechanicalReduction>1.25</mechanicalReduction>
        </actuator>
    </transmission>
    <transmission name="rob1_joint_5_transmission">
        <type>transmission_interface/SimpleTransmission</type>
        <joint name="rob1_joint_5">
            <hardwareInterface>hardware_interface/EffortJointInterface</hardwareInterface>
        </joint>
        <actuator name="rob1_joint_5_motor">
            <hardwareInterface>hardware_interface/EffortJointInterface</hardwareInterface>
            <mechanicalReduction>50</mechanicalReduction>
        </actuator>
    </transmission>
    <transmission name="rob1_joint_6_transmission">
        <type>transmission_interface/SimpleTransmission</type>
        <joint name="rob1_joint_6">
            <hardwareInterface>hardware_interface/EffortJointInterface</hardwareInterface>
        </joint>
        <actuator name="rob1_joint_6_motor">
            <hardwareInterface>hardware_interface/EffortJointInterface</hardwareInterface>
            <mechanicalReduction>30</mechanicalReduction>
        </actuator>
    </transmission>
    <transmission name="rob1_joint_1_transmission">
        <type>transmission_interface/SimpleTransmission</type>
        <joint name="rob1_joint_1">
            <hardwareInterface>hardware_interface/VelocityJointInterface</hardwareInterface>
        </joint>
        <actuator name="rob1_joint_1_motor">
            <hardwareInterface>hardware_interface/VelocityJointInterface</hardwareInterface>
            <mechanicalReduction>1.5</mechanicalReduction>
        </actuator>
    </transmission>
    <transmission name="rob1_joint_2_transmission">
        <type>transmission_interface/SimpleTransmission</type>
        <joint name="rob1_joint_2">
            <hardwareInterface>hardware_interface/VelocityJointInterface</hardwareInterface>
        </joint>
        <actuator name="rob1_joint_2_motor">
            <hardwareInterface>hardware_interface/VelocityJointInterface</hardwareInterface>
            <mechanicalReduction>100</mechanicalReduction>
        </actuator>
    </transmission>
    <transmission name="rob1_joint_3_transmission">
        <type>transmission_interface/SimpleTransmission</type>
        <joint name="rob1_joint_3">
            <hardwareInterface>hardware_interface/VelocityJointInterface</hardwareInterface>
        </joint>
        <actuator name="rob1_joint_3_motor">
            <hardwareInterface>hardware_interface/VelocityJointInterface</hardwareInterface>
            <mechanicalReduction>50</mechanicalReduction>
        </actuator>
    </transmission>
    <transmission name="rob1_joint_4_transmission">
        <type>transmission_interface/SimpleTransmission</type>
        <joint name="rob1_joint_4">
            <hardwareInterface>hardware_interface/VelocityJointInterface</hardwareInterface>
        </joint>
        <actuator name="rob1_joint_4_motor">
            <hardwareInterface>hardware_interface/VelocityJointInterface</hardwareInterface>
            <mechanicalReduction>1.25</mechanicalReduction>
        </actuator>
    </transmission>
    <transmission name="rob1_joint_5_transmission">
        <type>transmission_interface/SimpleTransmission</type>
        <joint name="rob1_joint_5">
            <hardwareInterface>hardware_interface/VelocityJointInterface</hardwareInterface>
        </joint>
        <actuator name="rob1_joint_5_motor">
            <hardwareInterface>hardware_interface/VelocityJointInterface</hardwareInterface>
            <mechanicalReduction>50</mechanicalReduction>
        </actuator>
    </transmission>
    <transmission name="rob1_joint_6_transmission">
        <type>transmission_interface/SimpleTransmission</type>
        <joint name="rob1_joint_6">
            <hardwareInterface>hardware_interface/VelocityJointInterface</hardwareInterface>
        </joint>
        <actuator name="rob1_joint_6_motor">
            <hardwareInterface>hardware_interface/VelocityJointInterface</hardwareInterface>
            <mechanicalReduction>30</mechanicalReduction>
        </actuator>
    </transmission>
    <transmission name="rob1_joint_1_transmission">
        <type>transmission_interface/SimpleTransmission</type>
        <joint name="rob1_joint_1">
            <hardwareInterface>hardware_interface/PositionJointInterface</hardwareInterface>
        </joint>
        <actuator name="rob1_joint_1_motor">
            <hardwareInterface>hardware_interface/PositionJointInterface</hardwareInterface>
            <mechanicalReduction>1.5</mechanicalReduction>
        </actuator>
    </transmission>
    <transmission name="rob1_joint_2_transmission">
        <type>transmission_interface/SimpleTransmission</type>
        <joint name="rob1_joint_2">
            <hardwareInterface>hardware_interface/PositionJointInterface</hardwareInterface>
        </joint>
        <actuator name="rob1_joint_2_motor">
            <hardwareInterface>hardware_interface/PositionJointInterface</hardwareInterface>
            <mechanicalReduction>100</mechanicalReduction>
        </actuator>
    </transmission>
    <transmission name="rob1_joint_3_transmission">
        <type>transmission_interface/SimpleTransmission</type>
        <joint name="rob1_joint_3">
            <hardwareInterface>hardware_interface/PositionJointInterface</hardwareInterface>
        </joint>
        <actuator name="rob1_joint_3_motor">
            <hardwareInterface>hardware_interface/PositionJointInterface</hardwareInterface>
            <mechanicalReduction>50</mechanicalReduction>
        </actuator>
    </transmission>
    <transmission name="rob1_joint_4_transmission">
        <type>transmission_interface/SimpleTransmission</type>
        <joint name="rob1_joint_4">
            <hardwareInterface>hardware_interface/PositionJointInterface</hardwareInterface>
        </joint>
        <actuator name="rob1_joint_4_motor">
            <hardwareInterface>hardware_interface/PositionJointInterface</hardwareInterface>
            <mechanicalReduction>1.25</mechanicalReduction>
        </actuator>
    </transmission>
    <transmission name="rob1_joint_5_transmission">
        <type>transmission_interface/SimpleTransmission</type>
        <joint name="rob1_joint_5">
            <hardwareInterface>hardware_interface/PositionJointInterface</hardwareInterface>
        </joint>
        <actuator name="rob1_joint_5_motor">
            <hardwareInterface>hardware_interface/PositionJointInterface</hardwareInterface>
            <mechanicalReduction>50</mechanicalReduction>
        </actuator>
    </transmission>
    <transmission name="rob1_joint_6_transmission">
        <type>transmission_interface/SimpleTransmission</type>
        <joint name="rob1_joint_6">
            <hardwareInterface>hardware_interface/PositionJointInterface</hardwareInterface>
        </joint>
        <actuator name="rob1_joint_6_motor">
            <hardwareInterface>hardware_interface/PositionJointInterface</hardwareInterface>
            <mechanicalReduction>30</mechanicalReduction>
        </actuator>
    </transmission>
    <transmission name="rob1_za_state">
        <type>za_hw/ZaStateInterface</type>
        <joint name="rob1_joint_1">
            <hardwareInterface>za_hw/ZaStateInterface</hardwareInterface>
        </joint>
        <joint name="rob1_joint_2">
            <hardwareInterface>za_hw/ZaStateInterface</hardwareInterface>
        </joint>
        <joint name="rob1_joint_3">
            <hardwareInterface>za_hw/ZaStateInterface</hardwareInterface>
        </joint>
        <joint name="rob1_joint_4">
            <hardwareInterface>za_hw/ZaStateInterface</hardwareInterface>
        </joint>
        <joint name="rob1_joint_5">
            <hardwareInterface>za_hw/ZaStateInterface</hardwareInterface>
        </joint>
        <joint name="rob1_joint_6">
            <hardwareInterface>za_hw/ZaStateInterface</hardwareInterface>
        </joint>
        <actuator name="rob1_motor_1">
            <hardwareInterface>za_hw/ZaStateInterface</hardwareInterface>
        </actuator>
        <actuator name="rob1_motor_2">
            <hardwareInterface>za_hw/ZaStateInterface</hardwareInterface>
        </actuator>
        <actuator name="rob1_motor_3">
            <hardwareInterface>za_hw/ZaStateInterface</hardwareInterface>
        </actuator>
        <actuator name="rob1_motor_4">
            <hardwareInterface>za_hw/ZaStateInterface</hardwareInterface>
        </actuator>
        <actuator name="rob1_motor_5">
            <hardwareInterface>za_hw/ZaStateInterface</hardwareInterface>
        </actuator>
        <actuator name="rob1_motor_6">
            <hardwareInterface>za_hw/ZaStateInterface</hardwareInterface>
        </actuator>
    </transmission>
    <transmission name="rob1_za_model">
        <type>za_hw/ZaModelInterface</type>
        <joint name="rob1_joint_1">
            <role>root</role>
            <hardwareInterface>za_hw/ZaModelInterface</hardwareInterface>
        </joint>
        <joint name="rob1_joint_6-flange">
            <role>tip</role>
            <hardwareInterface>za_hw/ZaModelInterface</hardwareInterface>
        </joint>
        <actuator name="rob1_joint_1_motor_root">
            <hardwareInterface>za_hw/ZaModelInterface</hardwareInterface>
        </actuator>
        <actuator name="rob1_joint_6-flange_motor_tip">
            <hardwareInterface>za_hw/ZaModelInterface</hardwareInterface>
        </actuator>
    </transmission>
    <!-- link list -->
    <link name="rob1_pedestal_base">
        <visual>
            <geometry>
                <mesh filename="package://hydra_description/meshes/visual/za_pedestal.dae" />
            </geometry>
        </visual>
        <collision>
            <geometry>
                <mesh filename="package://hydra_description/meshes/collision/za_pedestal_collision.stl" />
            </geometry>
        </collision>
        <inertial>
            <mass value="0.1" />
            <origin xyz="0 0 0" rpy="0 0 0" />
            <inertia ixx="0.03" iyy="0.03" izz="0.03" ixy="0.0" ixz="0.0" iyz="0.0" />
        </inertial>
    </link>
    <link name="rob1_pedestal_top" />
    <joint name="rob1_pedestal_base-rob1_pedestal_top" type="fixed">
        <origin rpy="0.0 0.0 0.0" xyz="0 0 0.585" />
        <parent link="rob1_pedestal_base" />
        <child link="rob1_pedestal_top" />
    </joint>
    <joint name="rob1_pedestal_top-rob1_base_link" type="fixed">
        <parent link="rob1_pedestal_top" />
        <child link="rob1_base_link" />
    </joint>
    &quot;
    <!-- link list -->
    <link name="rob2_base_link">
        <visual>
            <geometry>
                <mesh filename="package://za_description/meshes/visual/base_link.dae" />
            </geometry>
        </visual>
        <collision>
            <geometry>
                <mesh filename="package://za_description/meshes/collision/base_link_collision.stl" />
            </geometry>
        </collision>
        <inertial>
            <origin xyz="-0.035356 -0.000003 0.142049" rpy="0 0 0" />
            <mass value="18.327" />
            <inertia ixx="0.185203" ixy="0.000006" ixz="0.016506" iyy="0.232301" iyz="0.000014" izz="0.163415" />
        </inertial>
    </link>
    <link name="rob2_link_1">
        <visual>
            <geometry>
                <mesh filename="package://za_description/meshes/visual/link_1.dae" />
            </geometry>
        </visual>
        <collision>
            <geometry>
                <mesh filename="package://za_description/meshes/collision/link_1_collision.stl" />
            </geometry>
        </collision>
        <inertial>
            <origin xyz="0.009612 0.016390 -0.065742" rpy="0 0 0" />
            <mass value="13.44" />
            <inertia ixx="0.178493" ixy="0.002772" ixz="0.010363" iyy="0.126756" iyz="0.016161" izz="0.130031" />
        </inertial>
    </link>
    <link name="rob2_link_2">
        <visual>
            <geometry>
                <mesh filename="package://za_description/meshes/visual/link_2.dae" />
            </geometry>
        </visual>
        <collision>
            <geometry>
                <mesh filename="package://za_description/meshes/collision/link_2_collision.stl" />
            </geometry>
        </collision>
        <inertial>
            <origin xyz="-0.003803 0.001296 0.191397" rpy="0 0 0" />
            <mass value="17.11" />
            <inertia ixx="0.740919" ixy="-0.003160" ixz="-0.003160" iyy="0.699365" iyz="0.039435" izz="0.100361" />
        </inertial>
    </link>
    <link name="rob2_link_3">
        <visual>
            <geometry>
                <mesh filename="package://za_description/meshes/visual/link_3.dae" />
            </geometry>
        </visual>
        <collision>
            <geometry>
                <mesh filename="package://za_description/meshes/collision/link_3_collision.stl" />
            </geometry>
        </collision>
        <inertial>
            <origin xyz="0.019381 -0.007200 -0.002694" rpy="0 0 0" />
            <mass value="7.33" />
            <inertia ixx="0.027465" ixy="0.001126" ixz="0.004749" iyy="0.037555" iyz="-0.000148" izz="0.031377" />
        </inertial>
    </link>
    <link name="rob2_link_4">
        <visual>
            <geometry>
                <mesh filename="package://za_description/meshes/visual/link_4.dae" />
            </geometry>
        </visual>
        <collision>
            <geometry>
                <mesh filename="package://za_description/meshes/collision/link_4_collision.stl" />
            </geometry>
        </collision>
        <inertial>
            <origin xyz="0.290062 0.005593 0.000640" rpy="0 0 0" />
            <mass value="6.11" />
            <inertia ixx="0.019909" ixy="0.003159" ixz="-0.000103" iyy="0.058941" iyz="-0.000022" izz="0.066959" />
        </inertial>
    </link>
    <link name="rob2_link_5">
        <visual>
            <geometry>
                <mesh filename="package://za_description/meshes/visual/link_5.dae" />
            </geometry>
        </visual>
        <collision>
            <geometry>
                <mesh filename="package://za_description/meshes/collision/link_5_collision.stl" />
            </geometry>
        </collision>
        <inertial>
            <origin xyz="0.009621 0.000953 0.000305" rpy="0 0 0" />
            <mass value="2.44" />
            <inertia ixx="0.002635" ixy="-0.000031" ixz="-0.000023" iyy="0.005551" iyz="0.000004" izz="0.005487" />
        </inertial>
    </link>
    <link name="rob2_link_6">
        <visual>
            <geometry>
                <mesh filename="package://za_description/meshes/visual/link_6.dae" />
            </geometry>
        </visual>
        <collision>
            <geometry>
                <mesh filename="package://za_description/meshes/collision/link_6_collision.stl" />
            </geometry>
        </collision>
        <inertial>
            <origin xyz="-0.012049 0.000000 0.000000" rpy="0 0 0" />
            <mass value="0.244" />
            <inertia ixx="0.000106" ixy="0.000000" ixz="0.000000" iyy="0.000064" iyz="0.000000" izz="0.000064" />
        </inertial>
    </link>
    <!-- joint list -->
    <joint name="rob2_joint_1" type="revolute">
        <origin rpy="0.0 0.0 0.0" xyz="0 0 0.45" />
        <axis xyz="0 0 1" />
        <parent link="rob2_base_link" />
        <child link="rob2_link_1" />
        <limit effort="500.0" lower="-2.96" upper="2.96" velocity="2.6" />
        <dynamics damping="0.003" friction="0.0" />
    </joint>
    <joint name="rob2_joint_2" type="revolute">
        <origin rpy="0.0 0.0 0.0" xyz="0.025 0 0.0" />
        <axis xyz="0 1 0" />
        <parent link="rob2_link_1" />
        <child link="rob2_link_2" />
        <limit effort="500.0" lower="-1.74" upper="2.35" velocity="1.9" />
        <dynamics damping="0.003" friction="0.0" />
    </joint>
    <joint name="rob2_joint_3" type="revolute">
        <origin rpy="0.0 0.0 0.0" xyz="0.0 -0.001 0.454" />
        <axis xyz="0 1 0" />
        <parent link="rob2_link_2" />
        <child link="rob2_link_3" />
        <limit effort="200.0" lower="-1.570796" upper="1.15" velocity="2.6" />
        <dynamics damping="0.003" friction="0.0" />
    </joint>
    <joint name="rob2_joint_4" type="revolute">
        <origin rpy="0.0 0.0 0.0" xyz="0.0 0.0 0.035" />
        <axis xyz="1 0 0" />
        <parent link="rob2_link_3" />
        <child link="rob2_link_4" />
        <limit effort="100.0" lower="-2.6" upper="2.6" velocity="3.5" />
        <dynamics damping="0.003" friction="0.0" />
    </joint>
    <joint name="rob2_joint_5" type="revolute">
        <origin rpy="0.0 0.0 0.0" xyz="0.4195 0.001 0.0" />
        <axis xyz="0 1 0" />
        <parent link="rob2_link_4" />
        <child link="rob2_link_5" />
        <limit effort="100.0" lower="-2.49" upper="2.49" velocity="3.9" />
        <dynamics damping="0.003" friction="0.0" />
    </joint>
    <joint name="rob2_joint_6" type="revolute">
        <origin rpy="0.0 0.0 0.0" xyz="0.1175 0.0 0.0" />
        <axis xyz="1 0 0" />
        <parent link="rob2_link_5" />
        <child link="rob2_link_6" />
        <limit effort="10.0" lower="-3.141592653589793" upper="3.141592653589793" velocity="6.283185307179586" />
        <dynamics damping="0.003" friction="0.0" />
    </joint>
    <!-- ROS-Industrial 'base' frame: base_link to Fanuc World Coordinates transform -->
    <link name="rob2_base" />
    <joint name="rob2_base_link-base" type="fixed">
        <origin rpy="0 0 0" xyz="0 0 0" />
        <axis xyz="0 0 1" />
        <parent link="rob2_base_link" />
        <child link="rob2_base" />
    </joint>
    <!-- ROS-Industrial 'flange' frame: attachment point for EEF models -->
    <link name="rob2_flange" />
    <joint name="rob2_joint_6-flange" type="fixed">
        <origin rpy="0 0 0" xyz="0 0 0" />
        <parent link="rob2_link_6" />
        <child link="rob2_flange" />
    </joint>
    <!-- ROS-Industrial 'tool0' frame: all-zeros tool frame -->
    <link name="rob2_tool0" />
    <joint name="rob2_link_6_tool0" type="fixed">
        <origin rpy="0 1.5707963267948966 0" xyz="0 0 0" />
        <parent link="rob2_flange" />
        <child link="rob2_tool0" />
    </joint>
    <transmission name="rob2_joint_1_transmission">
        <type>transmission_interface/SimpleTransmission</type>
        <joint name="rob2_joint_1">
            <hardwareInterface>hardware_interface/EffortJointInterface</hardwareInterface>
        </joint>
        <actuator name="rob2_joint_1_motor">
            <hardwareInterface>hardware_interface/EffortJointInterface</hardwareInterface>
            <mechanicalReduction>1.5</mechanicalReduction>
        </actuator>
    </transmission>
    <transmission name="rob2_joint_2_transmission">
        <type>transmission_interface/SimpleTransmission</type>
        <joint name="rob2_joint_2">
            <hardwareInterface>hardware_interface/EffortJointInterface</hardwareInterface>
        </joint>
        <actuator name="rob2_joint_2_motor">
            <hardwareInterface>hardware_interface/EffortJointInterface</hardwareInterface>
            <mechanicalReduction>100</mechanicalReduction>
        </actuator>
    </transmission>
    <transmission name="rob2_joint_3_transmission">
        <type>transmission_interface/SimpleTransmission</type>
        <joint name="rob2_joint_3">
            <hardwareInterface>hardware_interface/EffortJointInterface</hardwareInterface>
        </joint>
        <actuator name="rob2_joint_3_motor">
            <hardwareInterface>hardware_interface/EffortJointInterface</hardwareInterface>
            <mechanicalReduction>50</mechanicalReduction>
        </actuator>
    </transmission>
    <transmission name="rob2_joint_4_transmission">
        <type>transmission_interface/SimpleTransmission</type>
        <joint name="rob2_joint_4">
            <hardwareInterface>hardware_interface/EffortJointInterface</hardwareInterface>
        </joint>
        <actuator name="rob2_joint_4_motor">
            <hardwareInterface>hardware_interface/EffortJointInterface</hardwareInterface>
            <mechanicalReduction>1.25</mechanicalReduction>
        </actuator>
    </transmission>
    <transmission name="rob2_joint_5_transmission">
        <type>transmission_interface/SimpleTransmission</type>
        <joint name="rob2_joint_5">
            <hardwareInterface>hardware_interface/EffortJointInterface</hardwareInterface>
        </joint>
        <actuator name="rob2_joint_5_motor">
            <hardwareInterface>hardware_interface/EffortJointInterface</hardwareInterface>
            <mechanicalReduction>50</mechanicalReduction>
        </actuator>
    </transmission>
    <transmission name="rob2_joint_6_transmission">
        <type>transmission_interface/SimpleTransmission</type>
        <joint name="rob2_joint_6">
            <hardwareInterface>hardware_interface/EffortJointInterface</hardwareInterface>
        </joint>
        <actuator name="rob2_joint_6_motor">
            <hardwareInterface>hardware_interface/EffortJointInterface</hardwareInterface>
            <mechanicalReduction>30</mechanicalReduction>
        </actuator>
    </transmission>
    <transmission name="rob2_joint_1_transmission">
        <type>transmission_interface/SimpleTransmission</type>
        <joint name="rob2_joint_1">
            <hardwareInterface>hardware_interface/VelocityJointInterface</hardwareInterface>
        </joint>
        <actuator name="rob2_joint_1_motor">
            <hardwareInterface>hardware_interface/VelocityJointInterface</hardwareInterface>
            <mechanicalReduction>1.5</mechanicalReduction>
        </actuator>
    </transmission>
    <transmission name="rob2_joint_2_transmission">
        <type>transmission_interface/SimpleTransmission</type>
        <joint name="rob2_joint_2">
            <hardwareInterface>hardware_interface/VelocityJointInterface</hardwareInterface>
        </joint>
        <actuator name="rob2_joint_2_motor">
            <hardwareInterface>hardware_interface/VelocityJointInterface</hardwareInterface>
            <mechanicalReduction>100</mechanicalReduction>
        </actuator>
    </transmission>
    <transmission name="rob2_joint_3_transmission">
        <type>transmission_interface/SimpleTransmission</type>
        <joint name="rob2_joint_3">
            <hardwareInterface>hardware_interface/VelocityJointInterface</hardwareInterface>
        </joint>
        <actuator name="rob2_joint_3_motor">
            <hardwareInterface>hardware_interface/VelocityJointInterface</hardwareInterface>
            <mechanicalReduction>50</mechanicalReduction>
        </actuator>
    </transmission>
    <transmission name="rob2_joint_4_transmission">
        <type>transmission_interface/SimpleTransmission</type>
        <joint name="rob2_joint_4">
            <hardwareInterface>hardware_interface/VelocityJointInterface</hardwareInterface>
        </joint>
        <actuator name="rob2_joint_4_motor">
            <hardwareInterface>hardware_interface/VelocityJointInterface</hardwareInterface>
            <mechanicalReduction>1.25</mechanicalReduction>
        </actuator>
    </transmission>
    <transmission name="rob2_joint_5_transmission">
        <type>transmission_interface/SimpleTransmission</type>
        <joint name="rob2_joint_5">
            <hardwareInterface>hardware_interface/VelocityJointInterface</hardwareInterface>
        </joint>
        <actuator name="rob2_joint_5_motor">
            <hardwareInterface>hardware_interface/VelocityJointInterface</hardwareInterface>
            <mechanicalReduction>50</mechanicalReduction>
        </actuator>
    </transmission>
    <transmission name="rob2_joint_6_transmission">
        <type>transmission_interface/SimpleTransmission</type>
        <joint name="rob2_joint_6">
            <hardwareInterface>hardware_interface/VelocityJointInterface</hardwareInterface>
        </joint>
        <actuator name="rob2_joint_6_motor">
            <hardwareInterface>hardware_interface/VelocityJointInterface</hardwareInterface>
            <mechanicalReduction>30</mechanicalReduction>
        </actuator>
    </transmission>
    <transmission name="rob2_joint_1_transmission">
        <type>transmission_interface/SimpleTransmission</type>
        <joint name="rob2_joint_1">
            <hardwareInterface>hardware_interface/PositionJointInterface</hardwareInterface>
        </joint>
        <actuator name="rob2_joint_1_motor">
            <hardwareInterface>hardware_interface/PositionJointInterface</hardwareInterface>
            <mechanicalReduction>1.5</mechanicalReduction>
        </actuator>
    </transmission>
    <transmission name="rob2_joint_2_transmission">
        <type>transmission_interface/SimpleTransmission</type>
        <joint name="rob2_joint_2">
            <hardwareInterface>hardware_interface/PositionJointInterface</hardwareInterface>
        </joint>
        <actuator name="rob2_joint_2_motor">
            <hardwareInterface>hardware_interface/PositionJointInterface</hardwareInterface>
            <mechanicalReduction>100</mechanicalReduction>
        </actuator>
    </transmission>
    <transmission name="rob2_joint_3_transmission">
        <type>transmission_interface/SimpleTransmission</type>
        <joint name="rob2_joint_3">
            <hardwareInterface>hardware_interface/PositionJointInterface</hardwareInterface>
        </joint>
        <actuator name="rob2_joint_3_motor">
            <hardwareInterface>hardware_interface/PositionJointInterface</hardwareInterface>
            <mechanicalReduction>50</mechanicalReduction>
        </actuator>
    </transmission>
    <transmission name="rob2_joint_4_transmission">
        <type>transmission_interface/SimpleTransmission</type>
        <joint name="rob2_joint_4">
            <hardwareInterface>hardware_interface/PositionJointInterface</hardwareInterface>
        </joint>
        <actuator name="rob2_joint_4_motor">
            <hardwareInterface>hardware_interface/PositionJointInterface</hardwareInterface>
            <mechanicalReduction>1.25</mechanicalReduction>
        </actuator>
    </transmission>
    <transmission name="rob2_joint_5_transmission">
        <type>transmission_interface/SimpleTransmission</type>
        <joint name="rob2_joint_5">
            <hardwareInterface>hardware_interface/PositionJointInterface</hardwareInterface>
        </joint>
        <actuator name="rob2_joint_5_motor">
            <hardwareInterface>hardware_interface/PositionJointInterface</hardwareInterface>
            <mechanicalReduction>50</mechanicalReduction>
        </actuator>
    </transmission>
    <transmission name="rob2_joint_6_transmission">
        <type>transmission_interface/SimpleTransmission</type>
        <joint name="rob2_joint_6">
            <hardwareInterface>hardware_interface/PositionJointInterface</hardwareInterface>
        </joint>
        <actuator name="rob2_joint_6_motor">
            <hardwareInterface>hardware_interface/PositionJointInterface</hardwareInterface>
            <mechanicalReduction>30</mechanicalReduction>
        </actuator>
    </transmission>
    <transmission name="rob2_za_state">
        <type>za_hw/ZaStateInterface</type>
        <joint name="rob2_joint_1">
            <hardwareInterface>za_hw/ZaStateInterface</hardwareInterface>
        </joint>
        <joint name="rob2_joint_2">
            <hardwareInterface>za_hw/ZaStateInterface</hardwareInterface>
        </joint>
        <joint name="rob2_joint_3">
            <hardwareInterface>za_hw/ZaStateInterface</hardwareInterface>
        </joint>
        <joint name="rob2_joint_4">
            <hardwareInterface>za_hw/ZaStateInterface</hardwareInterface>
        </joint>
        <joint name="rob2_joint_5">
            <hardwareInterface>za_hw/ZaStateInterface</hardwareInterface>
        </joint>
        <joint name="rob2_joint_6">
            <hardwareInterface>za_hw/ZaStateInterface</hardwareInterface>
        </joint>
        <actuator name="rob2_motor_1">
            <hardwareInterface>za_hw/ZaStateInterface</hardwareInterface>
        </actuator>
        <actuator name="rob2_motor_2">
            <hardwareInterface>za_hw/ZaStateInterface</hardwareInterface>
        </actuator>
        <actuator name="rob2_motor_3">
            <hardwareInterface>za_hw/ZaStateInterface</hardwareInterface>
        </actuator>
        <actuator name="rob2_motor_4">
            <hardwareInterface>za_hw/ZaStateInterface</hardwareInterface>
        </actuator>
        <actuator name="rob2_motor_5">
            <hardwareInterface>za_hw/ZaStateInterface</hardwareInterface>
        </actuator>
        <actuator name="rob2_motor_6">
            <hardwareInterface>za_hw/ZaStateInterface</hardwareInterface>
        </actuator>
    </transmission>
    <transmission name="rob2_za_model">
        <type>za_hw/ZaModelInterface</type>
        <joint name="rob2_joint_1">
            <role>root</role>
            <hardwareInterface>za_hw/ZaModelInterface</hardwareInterface>
        </joint>
        <joint name="rob2_joint_6-flange">
            <role>tip</role>
            <hardwareInterface>za_hw/ZaModelInterface</hardwareInterface>
        </joint>
        <actuator name="rob2_joint_1_motor_root">
            <hardwareInterface>za_hw/ZaModelInterface</hardwareInterface>
        </actuator>
        <actuator name="rob2_joint_6-flange_motor_tip">
            <hardwareInterface>za_hw/ZaModelInterface</hardwareInterface>
        </actuator>
    </transmission>
    <link name="rob2_pedestal_base">
        <visual>
            <geometry>
                <mesh filename="package://hydra_description/meshes/visual/za_pedestal.dae" />
            </geometry>
        </visual>
        <collision>
            <geometry>
                <mesh filename="package://hydra_description/meshes/collision/za_pedestal_collision.stl" />
            </geometry>
        </collision>
        <inertial>
            <mass value="0.1" />
            <origin xyz="0 0 0" rpy="0 0 0" />
            <inertia ixx="0.03" iyy="0.03" izz="0.03" ixy="0.0" ixz="0.0" iyz="0.0" />
        </inertial>
    </link>
    <link name="rob2_pedestal_top" />
    <joint name="rob2_pedestal_base-rob2_pedestal_top" type="fixed">
        <origin rpy="0.0 0.0 0.0" xyz="0 0 0.585" />
        <parent link="rob2_pedestal_base" />
        <child link="rob2_pedestal_top" />
    </joint>
    <joint name="rob2_pedestal_top-rob2_base_link" type="fixed">
        <parent link="rob2_pedestal_top" />
        <child link="rob2_base_link" />
    </joint>
    <link name="hydra_base" />
    <link name="optical_table" />
    <!-- link list -->
    <link name="optical_table_base">
        <visual>
            <geometry>
                <mesh filename="package://hydra_description/meshes/visual/optical_table.dae" />
            </geometry>
        </visual>
        <collision>
            <geometry>
                <mesh filename="package://hydra_description/meshes/collision/optical_table.stl" />
            </geometry>
        </collision>
        <inertial>
            <mass value="0.1" />
            <origin xyz="0 0 0" rpy="0 0 0" />
            <inertia ixx="0.03" iyy="0.03" izz="0.03" ixy="0.0" ixz="0.0" iyz="0.0" />
        </inertial>
    </link>
    <!-- joint list -->
    <joint name="hydra_base-optical_table_base" type="fixed">
        <parent link="hydra_base" />
        <child link="optical_table_base" />
    </joint>
    <joint name="optical_table_base-optical_table" type="fixed">
        <origin rpy="0.0 0.0 0.0" xyz="0 0 0.05842" />
        <parent link="optical_table_base" />
        <child link="optical_table" />
    </joint>
    <joint name="hydra_base-rob1_pedestal_base" type="fixed">
        <origin rpy="0 0 1.5707963267948966" xyz="0 -0.79375  0" />
        <parent link="optical_table" />
        <child link="rob1_pedestal_base" />
    </joint>
    <joint name="hydra_base-rob2_pedestal_base" type="fixed">
        <origin rpy="0 0 -1.5707963267948966" xyz="0 0.79375 0" />
        <parent link="optical_table" />
        <child link="rob2_pedestal_base" />
    </joint>
    <transmission name="hydra_model">
        <type>hydra_hw/HydraModelInterface</type>
        <joint name="positioner_joint">
            <role>positioner</role>
            <hardwareInterface>hydra_hw/HydraModelInterface</hardwareInterface>
        </joint>
        <actuator name="_motor_positioner_joint">
            <hardwareInterface>hydra_hw/HydraModelInterface</hardwareInterface>
        </actuator>
    </transmission>
    <link name="world" />
    <joint name="world-hydra_base" type="fixed">
        <parent link="world" />
        <child link="hydra_base" />
    </joint>
    <!-- Gazebo plugin for ROS Control -->
    <gazebo>
        <plugin filename="libgazebo_ros_control.so" name="gazebo_ros_control">
            <controlPeriod>0.001</controlPeriod>
            <robotSimType>hydra_gazebo/HydraHWSim</robotSimType>
            <robotNamespace>/</robotNamespace>
        </plugin>
        <self_collide>true</self_collide>
    </gazebo>
</robot>

